Workbook

Sheet Backup
A1: Receive Date | B1: Return Date | C1: Invoice Day | D1: Transaction Type | E1: Quantity | F1: Net Receipts | G1: Net Receipts Currency | H1: List Price | I1: List Price Currency | J1: Rebate In Agreement Currency | K1: Rebate per Units | L1: Price per unit | M1: Agreement Currency | N1: Rebate In Purchase Order Currency | O1: Purchase Order Currency | P1: Purchase Order | Q1: Asin | R1: UPC | S1: EAN | T1: Manufacturer | U1: Distributor | V1: Product Group | W1: Category | X1: Subcategory | Y1: Title | Z1: Product Description | AA1: Binding | AB1: Cost Currency | AC1: Old Cost | AD1: New Cost | AE1: Price Protection Agreement | AF1: Price Protection Day | AG1: Cost Variance | AH1: Invoice | AI1: Multi-Country Parent Agreement ID | AJ1: Invoice Concate
A2: 2022-12-16 | D2: Distributor Shipment | E2: 12 | F2: 1893.12 | G2: EUR | H2: 3137.76 | I2: EUR | J2: 64.36608 | K2: =J2/E2 -> 5.36384 | L2: =F2/E2 -> 157.76 | M2: EUR | N2: 64.36608 | O2: EUR | P2: 4A3KDTEZ | Q2: B079Z3DSBK | S2: 5099206076778 | T2: LOGC8 | U2: L***8 | V2: 147 | W2: 14700900 | X2: 14700939 | Y2: Logitech G X56 H.O.T.A.S Controller Acceleratore e Joystick RGB X56 HOTAS, 6 DoF Gradi di ‎Libertà, 4 Opzioni Tensionamento, +189 Controlli Programmabili, illuminazione RGB, 2x USB, PC ‎‎- Nero | AA2: accessory | AJ2: =P2&Q2 -> 4A3KDTEZB079Z3DSBK
A3: 2022-12-07 | D3: Distributor Shipment | E3: 4 | F3: 335.56 | G3: EUR | H3: 540.96 | I3: EUR | J3: 11.40904 | K3: =J3/E3 -> 2.85226 | L3: =F3/E3 -> 83.89 | M3: EUR | N3: 11.40904 | O3: EUR | P3: 3A946EXY | Q3: B07W6G3KBL | S3: 5099206107090 | T3: LOGC8 | U3: L***8 | V3: 147 | W3: 14700900 | X3: 14700933 | Y3: Logitech G PRO X SUPERLIGHT Mouse Gaming Wireless, Leggero 63 g, Sensore HERO 25K, 25.600 DPI, 5 Tasti Programmabili, Lunga Autonomia, Memoria Integrata, per eSport, PC / Mac - Rosso | AA3: pc | AJ3: =P3&Q3 -> 3A946EXYB07W6G3KBL
A4: 2022-12-21 | D4: Distributor Shipment | E4: 4 | F4: 257.68 | G4: EUR | H4: 377 | I4: EUR | J4: 8.76112 | K4: =J4/E4 -> 2.19028 | L4: =F4/E4 -> 64.42 | M4: EUR | N4: 8.76112 | O4: EUR | P4: 3GBCH66M | Q4: B0055ZWOZ4 | S4: 5099206027183 | T4: LOGC8 | U4: L***8 | V4: 147 | W4: 14700900 | X4: 14700930 | Y4: Logitech K750 Tastiera Solare Wireless per Windows, Layout Spagnolo QWERTY - Nero | AA4: pc | AJ4: =P4&Q4 -> 3GBCH66MB0055ZWOZ4
A5: 2022-12-30 | D5: Distributor Shipment | E5: 8 | F5: 210.96 | G5: EUR | H5: 354 | I5: EUR | J5: 7.17264 | K5: =J5/E5 -> 0.89658 | L5: =F5/E5 -> 26.37 | M5: EUR | N5: 7.17264 | O5: EUR | P5: 7H9X1Z6S | Q5: B00Q6MR0UO | S5: 5099206053830 | T5: LOGC8 | U5: L***8 | V5: 147 | W5: 14700900 | X5: 14700933 | Y5: Logitech G300s Mouse Gaming Ottico, 2.500 DPI, RGB, Design Leggero, 9 Pulsanti ‎ Programmabili, Memoria Integrata, Per Entrambe le Mani, Compatibile con PC/Mac/Laptop, Nero | AA5: accessory | AJ5: =P5&Q5 -> 7H9X1Z6SB00Q6MR0UO
A6: 2022-12-16 | D6: Distributor Shipment | E6: 8 | F6: 324.8 | G6: EUR | H6: 472.08 | I6: EUR | J6: 11.0432 | K6: =J6/E6 -> 1.3804 | L6: =F6/E6 -> 40.6 | M6: EUR | N6: 11.0432 | O6: EUR | P6: 2TMBDXBK | Q6: B07W4DHZLS | S6: 5099206094123 | T6: LOGC8 | U6: L***8 | V6: 147 | W6: 14700900 | X6: 14700930 | Y6: Logitech Keys-To-Go Tastiera Bluetooth, Sottile e Leggera, per iPhone, iPad, Apple TV e tutti i dispositivi iOS, Layout Italiano QWERTY - Rosa | AA6: pc | AJ6: =P6&Q6 -> 2TMBDXBKB07W4DHZLS
A7: 2022-12-27 | D7: Distributor Shipment | E7: 4 | F7: 301.64 | G7: EUR | H7: 442.6 | I7: EUR | J7: 10.25576 | K7: =J7/E7 -> 2.56394 | L7: =F7/E7 -> 75.41 | M7: EUR | N7: 10.25576 | O7: EUR | P7: 4GF112AE | Q7: B07W4DGFSM | S7: 5099206103733 | T7: LOGC8 | U7: L***8 | V7: 147 | W7: 14700900 | X7: 14700933 | Y7: Logitech MX Master 3S - Mouse Wireless ad Alte Prestazioni, Scorrimento Ultraveloce, Ergo, 8K DPI, Tracciamento su Vetro, Clic Silenziosi, USB C, Bluetooth, Windows, Linux, Chrome - Grigio chiaro | AA7: accessory | AJ7: =P7&Q7 -> 4GF112AEB07W4DGFSM
A8: 2022-12-29 | D8: Distributor Shipment | E8: 50 | F8: 468 | G8: EUR | H8: 696.5 | I8: EUR | J8: 15.912 | K8: =J8/E8 -> 0.31824 | L8: =F8/E8 -> 9.36 | M8: EUR | N8: 15.912 | O8: EUR | P8: 4E16R26M | Q8: B003V0QEV0 | S8: 5099206021341 | T8: LOGC8 | U8: L***8 | V8: 147 | W8: 14700900 | X8: 14700930 | Y8: Logitech K120 Tastiera Cablata, Layout ‎Francese Azerty | AA8: pc | AJ8: =P8&Q8 -> 4E16R26MB003V0QEV0
A9: 2022-12-16 | D9: Distributor Shipment | E9: 1 | F9: 210.52 | G9: EUR | H9: 336.06 | I9: EUR | J9: 7.15768 | K9: =J9/E9 -> 7.15768 | L9: =F9/E9 -> 210.52 | M9: EUR | N9: 7.15768 | O9: EUR | P9: 4A3KDTEZ | Q9: B07W6JB7N7 | S9: 5099206082809 | T9: LOGC8 | U9: L***8 | V9: 147 | W9: 14700900 | X9: 14700939 | Y9: Logitech G923 Volante da Corsa e Pedali per PS5, PS4 e PC, UK Inglese Spina di Alimentazione Tipo G, Nero | AA9: pc | AJ9: =P9&Q9 -> 4A3KDTEZB07W6JB7N7
A10: 2022-12-16 | D10: Distributor Shipment | E10: 70 | F10: 655.2 | G10: EUR | H10: 975.1 | I10: EUR | J10: 22.2768 | K10: =J10/E10 -> 0.31824 | L10: =F10/E10 -> 9.36 | M10: EUR | N10: 22.2768 | O10: EUR | P10: 2TMBDXBK | Q10: B01A9GXEOI | R10: 777060019746 | S10: 5099206062856 | T10: LOGC8 | U10: L***8 | V10: 147 | W10: 14700900 | X10: 14700933 | Y10: Logitech M171 Mouse Wireless, 2.4 GHz con Mini Ricevitore USB, Rilevamento Ottico, Durata ‎Batteria Fino a 12 Mesi, Mouse Ambidestro per PC/Mac/Laptop, Nero | AA10: accessory | AJ10: =P10&Q10 -> 2TMBDXBKB01A9GXEOI
A11: 2022-12-17 | D11: Distributor Shipment | E11: 60 | F11: 1867.2 | G11: EUR | H11: 2360.4 | I11: EUR | J11: 63.4848 | K11: =J11/E11 -> 1.05808 | L11: =F11/E11 -> 31.12 | M11: EUR | N11: 63.4848 | O11: EUR | P11: 2W68T8TO | Q11: B07W5JKBMG | S11: 5099206093867 | T11: LOGC8 | U11: L***8 | V11: 147 | W11: 14701000 | X11: 14701080 | Y11: ASTRO Gaming Adattatore HDMI per PS5, Estrattore Audio HDMI 4K a Ottico TOSLINK SPDIF, Compatibile con Stazione Base A50, Auricolare con Microfono A20 per Giochi PlayStation 5 | AA11: consumer_electronics | AJ11: =P11&Q11 -> 2W68T8TOB07W5JKBMG
A12: 2022-12-06 | D12: Distributor Shipment | E12: 12 | F12: 1455 | G12: EUR | H12: 2055.6 | I12: EUR | J12: 49.47 | K12: =J12/E12 -> 4.1225 | L12: =F12/E12 -> 121.25 | M12: EUR | N12: 49.47 | O12: EUR | P12: 7EMS2FPG | Q12: B074KGS5C3 | S12: 5099206072800 | T12: LOGC8 | U12: L***8 | V12: 147 | W12: 14700900 | X12: 14700930 | Y12: Logitech Craft Tastiera, Layout Tedesco ‎Qwertz | AA12: accessory | AJ12: =P12&Q12 -> 7EMS2FPGB074KGS5C3
A13: 2022-12-29 | D13: Distributor Shipment | E13: 276 | F13: 7278.12 | G13: EUR | H13: 12213 | I13: EUR | J13: 247.45608 | K13: =J13/E13 -> 0.89658 | L13: =F13/E13 -> 26.37 | M13: EUR | N13: 247.45608 | O13: EUR | P13: 7H9X1Z6S | Q13: B00Q6MR0UO | S13: 5099206053830 | T13: LOGC8 | U13: L***8 | V13: 147 | W13: 14700900 | X13: 14700933 | Y13: Logitech G300s Mouse Gaming Ottico, 2.500 DPI, RGB, Design Leggero, 9 Pulsanti ‎ Programmabili, Memoria Integrata, Per Entrambe le Mani, Compatibile con PC/Mac/Laptop, Nero | AA13: accessory | AJ13: =P13&Q13 -> 7H9X1Z6SB00Q6MR0UO
A14: 2022-12-22 | D14: Distributor Shipment | E14: 40 | F14: 655.6 | G14: EUR | H14: 983.2 | I14: EUR | J14: 22.2904 | K14: =J14/E14 -> 0.55726 | L14: =F14/E14 -> 16.39 | M14: EUR | N14: 22.2904 | O14: EUR | P14: 2M7QFTCO | Q14: B07W7JYP91 | S14: 5099206085695 | T14: LOGC8 | U14: L***8 | V14: 147 | W14: 14700900 | X14: 14700933 | Y14: Logitech Pebble Mouse Wireless, Bluetooth o 2,4 GHz con Mini Ricevitore USB, Silenzioso, Mouse per ‎Computer Sottile, Clic silenziosi, per PC/Mac/Laptop/iPadOS/Chromebook - Verde | AA14: pc | AJ14: =P14&Q14 -> 2M7QFTCOB07W7JYP91
A15: 2022-12-06 | D15: Distributor Shipment | E15: 24 | F15: 278.4 | G15: EUR | H15: 471.84 | I15: EUR | J15: 9.4656 | K15: =J15/E15 -> 0.3944 | L15: =F15/E15 -> 11.6 | M15: EUR | N15: 9.4656 | O15: EUR | P15: 2CLMXQWQ | Q15: B07W7K29YK | S15: 5099206104389 | T15: LOGC8 | U15: L***8 | V15: 147 | W15: 14700900 | X15: 14700933 | Y15: Logitech G G440 Gaming Mouse Pad Rigido, Ottimizzato per i Sensori da Gioco, Attrito Moderato, Antiscivolo, Accessori da Gioco per Mac e PC, 340 x 280 x 5 mm | AA15: consumer_electronics | AJ15: =P15&Q15 -> 2CLMXQWQB07W7K29YK
A16: 2022-12-23 | D16: Distributor Shipment | E16: 4 | F16: 105.48 | G16: EUR | H16: 177 | I16: EUR | J16: 3.58632 | K16: =J16/E16 -> 0.89658 | L16: =F16/E16 -> 26.37 | M16: EUR | N16: 3.58632 | O16: EUR | P16: 7H9X1Z6S | Q16: B00Q6MR0UO | S16: 5099206053830 | T16: LOGC8 | U16: L***8 | V16: 147 | W16: 14700900 | X16: 14700933 | Y16: Logitech G300s Mouse Gaming Ottico, 2.500 DPI, RGB, Design Leggero, 9 Pulsanti ‎ Programmabili, Memoria Integrata, Per Entrambe le Mani, Compatibile con PC/Mac/Laptop, Nero | AA16: accessory | AJ16: =P16&Q16 -> 7H9X1Z6SB00Q6MR0UO
A17: 2022-12-06 | D17: Distributor Shipment | E17: 10 | F17: 322.1 | G17: EUR | H17: 483.5 | I17: EUR | J17: 10.9514 | K17: =J17/E17 -> 1.09514 | L17: =F17/E17 -> 32.21 | M17: EUR | N17: 10.9514 | O17: EUR | P17: 3A946EXY | Q17: B015BCWNNS | S17: 5099206059481 | T17: LOGC8 | U17: L***8 | V17: 147 | W17: 14700900 | X17: 14700930 | Y17: Logitech K400 PLUS Tastiera Wireless, Layout Ceco-Slovacco Qwerty, Nero | AA17: pc | AJ17: =P17&Q17 -> 3A946EXYB015BCWNNS
A18: 2022-12-29 | D18: Distributor Shipment | E18: 6 | F18: 158.1 | G18: EUR | H18: 236.04 | I18: EUR | J18: 5.3754 | K18: =J18/E18 -> 0.8959 | L18: =F18/E18 -> 26.35 | M18: EUR | N18: 5.3754 | O18: EUR | P18: 243WWSUA | Q18: B00DN1D1MW | S18: 5099206039148 | T18: LOGC8 | U18: L***8 | V18: 147 | W18: 14700900 | X18: 14700930 | Y18: Logitech MK270 Combo Tastiera e Mouse Wireless per Windows, Layout Internazionale QWERTY - Nero | AA18: pc | AJ18: =P18&Q18 -> 243WWSUAB00DN1D1MW
A19: 2022-12-13 | D19: Distributor Shipment | E19: 30 | F19: 280.8 | G19: EUR | H19: 417.9 | I19: EUR | J19: 9.5472 | K19: =J19/E19 -> 0.31824 | L19: =F19/E19 -> 9.36 | M19: EUR | N19: 9.5472 | O19: EUR | P19: 31DJDC7Q | Q19: B01A9GXEOI | R19: 777060019746 | S19: 5099206062856 | T19: LOGC8 | U19: L***8 | V19: 147 | W19: 14700900 | X19: 14700933 | Y19: Logitech M171 Mouse Wireless, 2.4 GHz con Mini Ricevitore USB, Rilevamento Ottico, Durata ‎Batteria Fino a 12 Mesi, Mouse Ambidestro per PC/Mac/Laptop, Nero | AA19: accessory | AJ19: =P19&Q19 -> 31DJDC7QB01A9GXEOI
A20: 2022-12-22 | D20: Distributor Shipment | E20: 16 | F20: 379.84 | G20: EUR | H20: 629.44 | I20: EUR | J20: 12.91456 | K20: =J20/E20 -> 0.80716 | L20: =F20/E20 -> 23.74 | M20: EUR | N20: 12.91456 | O20: EUR | P20: 5MWU8WTD | Q20: B07W6HBBMH | S20: 5099206104303 | T20: LOGC8 | U20: L***8 | V20: 147 | W20: 14700900 | X20: 14700933 | Y20: Logitech G G840 Gaming Mouse Pad XL, Ottimizzato per i Sensori da Gioco, Attrito Moderato, Antiscivolo, Accessori da Gioco per Mac e PC, 900 x 400 x 3 mm | AA20: consumer_electronics | AJ20: =P20&Q20 -> 5MWU8WTDB07W6HBBMH
A21: 2022-12-06 | D21: Distributor Shipment | E21: 48 | F21: 5568.96 | G21: EUR | H21: 7868.64 | I21: EUR | J21: 189.34464 | K21: =J21/E21 -> 3.94468 | L21: =F21/E21 -> 116.02 | M21: EUR | N21: 189.34464 | O21: EUR | P21: 2CLMXQWQ | Q21: B07W6HPP3R | S21: 5099206096134 | T21: LOGC8 | U21: L***8 | V21: 147 | W21: 14700900 | X21: 14700930 | Y21: Logitech Combo Touch Custodia con Tastiera per iPad Air (4 e 5 gen - 2020, 2022), Layout UK/US QWERTY - Grigio | AA21: pc | AJ21: =P21&Q21 -> 2CLMXQWQB07W6HPP3R
A22: 2022-12-19 | D22: Distributor Shipment | E22: 16 | F22: 328 | G22: EUR | H22: 655.04 | I22: EUR | J22: 11.152 | K22: =J22/E22 -> 0.697 | L22: =F22/E22 -> 20.5 | M22: EUR | N22: 11.152 | O22: EUR | P22: 7RAC5F9E | Q22: B002L3TSLQ | R22: 758399157934 | S22: 3610480106092 | T22: LOGC8 | U22: L***8 | V22: 147 | W22: 14700900 | X22: 14700930 | Y22: Logitech R400 Puntatore Laser per Presentazioni Wireless, 2.4 GHz e Bluetooth, Ricevitore USB, ‎Puntatore Laser Rosso, Portata 15 m, 6 Pulsanti, Controllo Intuitivo, Indicatore ‎Batteria, PC, Nero | AA22: consumer_electronics | AJ22: =P22&Q22 -> 7RAC5F9EB002L3TSLQ
A23: 2022-12-16 | D23: Distributor Shipment | E23: 176 | F23: 7145.6 | G23: EUR | H23: 10385.76 | I23: EUR | J23: 242.9504 | K23: =J23/E23 -> 1.3804 | L23: =F23/E23 -> 40.6 | M23: EUR | N23: 242.9504 | O23: EUR | P23: 36BT7GGL | Q23: B00O8K42PM | S23: 5099206055490 | T23: LOGC8 | U23: L***8 | V23: 147 | W23: 14700900 | X23: 14700930 | Y23: Logitech Keys-To-Go Tastiera Bluetooth, Layout Spagnolo QWERTY - Nero | AA23: accessory | AJ23: =P23&Q23 -> 36BT7GGLB00O8K42PM
A24: 2022-12-16 | D24: Distributor Shipment | E24: 336 | F24: 6888 | G24: EUR | H24: 13755.84 | I24: EUR | J24: 234.192 | K24: =J24/E24 -> 0.697 | L24: =F24/E24 -> 20.5 | M24: EUR | N24: 234.192 | O24: EUR | P24: 7RAC5F9E | Q24: B002L3TSLQ | R24: 758399157934 | S24: 3610480106092 | T24: LOGC8 | U24: L***8 | V24: 147 | W24: 14700900 | X24: 14700930 | Y24: Logitech R400 Puntatore Laser per Presentazioni Wireless, 2.4 GHz e Bluetooth, Ricevitore USB, ‎Puntatore Laser Rosso, Portata 15 m, 6 Pulsanti, Controllo Intuitivo, Indicatore ‎Batteria, PC, Nero | AA24: consumer_electronics | AJ24: =P24&Q24 -> 7RAC5F9EB002L3TSLQ
A25: 2022-12-16 | D25: Distributor Shipment | E25: 80 | F25: 656 | G25: EUR | H25: 983.2 | I25: EUR | J25: 22.304 | K25: =J25/E25 -> 0.2788 | L25: =F25/E25 -> 8.2 | M25: EUR | N25: 22.304 | O25: EUR | P25: 3UDP1VLY | Q25: B07W6JKH17 | S25: 5099206091627 | T25: LOGC8 | U25: L***8 | V25: 147 | W25: 14700900 | X25: 14700933 | Y25: Logitech USB Unifying Receiver - Nero | AA25: consumer_electronics | AJ25: =P25&Q25 -> 3UDP1VLYB07W6JKH17
A26: 2022-12-13 | D26: Distributor Shipment | E26: 16 | F26: 1648.96 | G26: EUR | H26: 2164 | I26: EUR | J26: 56.06464 | K26: =J26/E26 -> 3.50404 | L26: =F26/E26 -> 103.06 | M26: EUR | N26: 56.06464 | O26: EUR | P26: 56UO2L2I | Q26: B07PPNT9B2 | S26: 5099206082977 | T26: LOGC8 | U26: L***8 | V26: 147 | W26: 14700900 | X26: 14700939 | Y26: ASTRO Gaming MixAmp Pro TR Amplificatore per Headset da Gaming, 4° Generazione, Dolby Audio, Funzionalità Scheda Audio USB, Digital Daisy-Chain, per PS5, PS4, PC, Mac, Nintendo Switch, Nero / Blu | AA26: pc | AJ26: =P26&Q26 -> 56UO2L2IB07PPNT9B2
A27: 2022-12-30 | D27: Distributor Shipment | E27: 176 | F27: 12907.84 | G27: EUR | H27: 20917.6 | I27: EUR | J27: 438.86656 | K27: =J27/E27 -> 2.49356 | L27: =F27/E27 -> 73.34 | M27: EUR | N27: 438.86656 | O27: EUR | P27: 7H9X1Z6S | Q27: B07W6JNQ82 | S27: 5099206086425 | T27: LOGC8 | U27: L***8 | V27: 147 | W27: 14700900 | X27: 14700930 | Y27: Logitech G PRO TKL Tastiera Gaming Meccanica, GX Blue Clicky Switch, LIGHTSYNC RGB, Design Portatile Tenkeyless, Pensato per Esport Gaming, Micro Cavo USB Rimovibile, QWERTY US Layout, Nero | AA27: pc | AJ27: =P27&Q27 -> 7H9X1Z6SB07W6JNQ82
A28: 2022-12-06 | D28: Distributor Shipment | E28: 4 | F28: 387.32 | G28: EUR | H28: 459 | I28: EUR | J28: 13.16888 | K28: =J28/E28 -> 3.29222 | L28: =F28/E28 -> 96.83 | M28: EUR | N28: 13.16888 | O28: EUR | P28: 5FPQ9KSZ | Q28: B07W4DHL8V | S28: 5099206106222 | T28: LOGC8 | U28: L***8 | V28: 267 | W28: 26704000 | X28: 26704200 | Y28: Logitech G Blue Yeti Kit Game Streaming con Microfono Gaming USB Yeti, Software Blue VO!CE, Temi Esclusivi Streamlabs, Filtro Pop Blu Personalizzato, PC/Mac/PS4/PS5 - Nero | AA28: consumer_electronics | AJ28: =P28&Q28 -> 5FPQ9KSZB07W4DHL8V
A29: 2022-12-22 | D29: Distributor Shipment | E29: 76 | F29: 5731.16 | G29: EUR | H29: 8409.4 | I29: EUR | J29: 194.85944 | K29: =J29/E29 -> 2.56394 | L29: =F29/E29 -> 75.41 | M29: EUR | N29: 194.85944 | O29: EUR | P29: 4GF112AE | Q29: B07W4DGFSM | S29: 5099206103733 | T29: LOGC8 | U29: L***8 | V29: 147 | W29: 14700900 | X29: 14700933 | Y29: Logitech MX Master 3S - Mouse Wireless ad Alte Prestazioni, Scorrimento Ultraveloce, Ergo, 8K DPI, Tracciamento su Vetro, Clic Silenziosi, USB C, Bluetooth, Windows, Linux, Chrome - Grigio chiaro | AA29: accessory | AJ29: =P29&Q29 -> 4GF112AEB07W4DGFSM
A30: 2022-12-13 | D30: Distributor Shipment | E30: 10 | F30: 175.6 | G30: EUR | H30: 270.4 | I30: EUR | J30: 5.9704 | K30: =J30/E30 -> 0.59704 | L30: =F30/E30 -> 17.56 | M30: EUR | N30: 5.9704 | O30: EUR | P30: 1KW92RHQ | Q30: B0042BVWZ0 | S30: 5099206020634 | T30: LOGC8 | U30: L***8 | V30: 147 | W30: 14700900 | X30: 14700930 | Y30: Logitech MK120 Kit Tastiera e Mouse Cablati, Layout Svizzero ‎Qwertz, Nero | AA30: pc | AJ30: =P30&Q30 -> 1KW92RHQB0042BVWZ0
A31: 2022-12-17 | D31: Distributor Shipment | E31: 4 | F31: 189.92 | G31: EUR | H31: 311.44 | I31: EUR | J31: 6.45728 | K31: =J31/E31 -> 1.61432 | L31: =F31/E31 -> 47.48 | M31: EUR | N31: 6.45728 | O31: EUR | P31: 8FQ2THMT | Q31: B07W7MQMDH | S31: 5099206101821 | T31: LOGC8 | U31: L***8 | V31: 147 | W31: 14700900 | X31: 14700930 | Y31: Logitech G413 SE Tastiera Meccanica Gaming Full Size - Tastiera Retroilluminata con Switch Meccanici Tattili, Anti-Ghosting, Compatibile con Windows, macOS, Layout Italiano QWERTY - Alluminio Nero | AA31: pc | AJ31: =P31&Q31 -> 8FQ2THMTB07W7MQMDH
A32: 2022-12-20 | D32: Distributor Shipment | E32: 20 | F32: 327.8 | G32: EUR | H32: 491.6 | I32: EUR | J32: 11.1452 | K32: =J32/E32 -> 0.55726 | L32: =F32/E32 -> 16.39 | M32: EUR | N32: 11.1452 | O32: EUR | P32: 7RAC5F9E | Q32: B01K7GEG9W | R32: 097855123381 | S32: 5099206066199 | T32: LOGC8 | U32: L***8 | V32: 147 | W32: 14700900 | X32: 14700933 | Y32: Logitech M220 SILENT Mouse Wireless, 2,4 GHz con Ricevitore USB, Tracciamento Ottico 1000 DPI, Durata Batteria di 18 Mesi, Ambidestro, Compatibile con PC, Mac, Laptop - Grigio | AA32: accessory | AJ32: =P32&Q32 -> 7RAC5F9EB01K7GEG9W
A33: 2022-12-13 | D33: Distributor Shipment | E33: 50 | F33: 468 | G33: EUR | H33: 696.5 | I33: EUR | J33: 15.912 | K33: =J33/E33 -> 0.31824 | L33: =F33/E33 -> 9.36 | M33: EUR | N33: 15.912 | O33: EUR | P33: 31QWZ6KB | Q33: B01A9GXEOI | R33: 777060019746 | S33: 5099206062856 | T33: LOGC8 | U33: L***8 | V33: 147 | W33: 14700900 | X33: 14700933 | Y33: Logitech M171 Mouse Wireless, 2.4 GHz con Mini Ricevitore USB, Rilevamento Ottico, Durata ‎Batteria Fino a 12 Mesi, Mouse Ambidestro per PC/Mac/Laptop, Nero | AA33: accessory | AJ33: =P33&Q33 -> 31QWZ6KBB01A9GXEOI
A34: 2022-12-16 | D34: Distributor Shipment | E34: 16 | F34: 1113.76 | G34: EUR | H34: 1691.84 | I34: EUR | J34: 37.86784 | K34: =J34/E34 -> 2.36674 | L34: =F34/E34 -> 69.61 | M34: EUR | N34: 37.86784 | O34: EUR | P34: 2R6FMUZD | Q34: B07W4DH65R | S34: 5099206107489 | T34: LOGC8 | U34: L***8 | V34: 147 | W34: 14700900 | X34: 14700930 | Y34: Logitech per iPad (10ª generazione) Custodia con tastiera | Slim Folio con tastiera wireless integrata (grafite) - English Layout | AA34: pc | AJ34: =P34&Q34 -> 2R6FMUZDB07W4DH65R
A35: 2022-12-29 | D35: Distributor Shipment | E35: 2870 | F35: 47039.3 | G35: EUR | H35: 70544.6 | I35: EUR | J35: 1599.3362 | K35: =J35/E35 -> 0.55726 | L35: =F35/E35 -> 16.39 | M35: EUR | N35: 1599.3362 | O35: EUR | P35: 2LZI7R4T | Q35: B077BT728N | S35: 5099206076679 | T35: LOGC8 | U35: L***8 | V35: 147 | W35: 14700900 | X35: 14700930 | Y35: Logitech K280e Pro Tastiera, Layout Tedesco ‎QWERTZ, Nero | AA35: pc | AJ35: =P35&Q35 -> 2LZI7R4TB077BT728N
A36: 2022-12-24 | D36: Distributor Shipment | E36: 8 | F36: 603.28 | G36: EUR | H36: 885.2 | I36: EUR | J36: 20.51152 | K36: =J36/E36 -> 2.56394 | L36: =F36/E36 -> 75.41 | M36: EUR | N36: 20.51152 | O36: EUR | P36: 4GF112AE | Q36: B07W4DGFSM | S36: 5099206103733 | T36: LOGC8 | U36: L***8 | V36: 147 | W36: 14700900 | X36: 14700933 | Y36: Logitech MX Master 3S - Mouse Wireless ad Alte Prestazioni, Scorrimento Ultraveloce, Ergo, 8K DPI, Tracciamento su Vetro, Clic Silenziosi, USB C, Bluetooth, Windows, Linux, Chrome - Grigio chiaro | AA36: accessory | AJ36: =P36&Q36 -> 4GF112AEB07W4DGFSM
A37: 2022-12-23 | D37: Distributor Shipment | E37: 4 | F37: 301.64 | G37: EUR | H37: 442.6 | I37: EUR | J37: 10.25576 | K37: =J37/E37 -> 2.56394 | L37: =F37/E37 -> 75.41 | M37: EUR | N37: 10.25576 | O37: EUR | P37: 4GF112AE | Q37: B07W4DGFSM | S37: 5099206103733 | T37: LOGC8 | U37: L***8 | V37: 147 | W37: 14700900 | X37: 14700933 | Y37: Logitech MX Master 3S - Mouse Wireless ad Alte Prestazioni, Scorrimento Ultraveloce, Ergo, 8K DPI, Tracciamento su Vetro, Clic Silenziosi, USB C, Bluetooth, Windows, Linux, Chrome - Grigio chiaro | AA37: accessory | AJ37: =P37&Q37 -> 4GF112AEB07W4DGFSM
A38: 2022-12-30 | D38: Distributor Shipment | E38: 24 | F38: 696.24 | G38: EUR | H38: 1160.4 | I38: EUR | J38: 23.67216 | K38: =J38/E38 -> 0.98634 | L38: =F38/E38 -> 29.01 | M38: EUR | N38: 23.67216 | O38: EUR | P38: 4F3XMHTV | Q38: B0766JZ8Q3 | S38: 5099206074552 | T38: LOGC8 | U38: L***8 | V38: 147 | W38: 22903000 | X38: 14700933 | Y38: Logitech G840 XL Tappetino Mouse Gaming in Tessuto, Mouse Pad 400x900 mm, Spessore 3 mm, Superficie Orientata alle Prestazioni, Basso Attrito, Solida Base in Gomma, Portatile, Nero | AA38: pc | AJ38: =P38&Q38 -> 4F3XMHTVB0766JZ8Q3
A39: 2022-12-22 | D39: Distributor Shipment | E39: 50 | F39: 468 | G39: EUR | H39: 696.5 | I39: EUR | J39: 15.912 | K39: =J39/E39 -> 0.31824 | L39: =F39/E39 -> 9.36 | M39: EUR | N39: 15.912 | O39: EUR | P39: 5MWU8WTD | Q39: B01A9HC69G | R39: 097855119230 | S39: 0097855119230 | T39: LOGC8 | U39: L***8 | V39: 147 | W39: 14700900 | X39: 14700933 | Y39: Logitech M171 Mouse Wireless, 2.4 GHz con Mini Ricevitore USB, Rilevamento Ottico, Durata ‎Batteria 12 Mesi, Mouse Ambidestro per PC/Mac/Laptop, Blu | AA39: accessory | AJ39: =P39&Q39 -> 5MWU8WTDB01A9HC69G
A40: 2022-12-06 | D40: Distributor Shipment | E40: 8 | F40: 882.16 | G40: EUR | H40: 1832 | I40: EUR | J40: 29.99344 | K40: =J40/E40 -> 3.74918 | L40: =F40/E40 -> 110.27 | M40: EUR | N40: 29.99344 | O40: EUR | P40: 1M3XYEGX | Q40: B07W7MSGPL | S40: 5099206082618 | T40: LOGC8 | U40: L***8 | V40: 23 | W40: 2305600 | X40: 2305630 | Y40: Logitech G Tastiera meccanica da gioco 815, Clicky GL con profilo piatto, LIGHTSYNC RGB, design sottile, 5 tasti G programmabili, comandi multimediali, layout tedesco QWERTZ | AA40: pc | AJ40: =P40&Q40 -> 1M3XYEGXB07W7MSGPL
...

Sheet Recon
A1: Claim Detail | E1: PO Detail | G1: Recon
A2: Concate | B2: Qty | C2: Invoice Price | D2: Invoice Rebate Amt | E2: Qty | F2: Price | G2: ASIN/PO Invalid | H2: Qty Check | I2: Claim Qty > PO Qty | J2: Price Variance
A3: 11FTNKDSB07W7LXYTR | B3: 8 | C3: =_xlfn.XLOOKUP(Recon!A3,[1]Backup!AJ:AJ,[1]Backup!L:L) -> 63.23 | D3: =_xlfn.XLOOKUP(Recon!A3,[1]Backup!AJ:AJ,[1]Backup!K:K) -> 2.14982 | E3: =SUMIF('[1]PO Report'!A:A,Recon!A3,'[1]PO Report'!P:P) -> 8 | F3: =VLOOKUP(A3,'[1]PO Report'!$A:$Z,15,0) -> 63.23 | H3: =B3-E3 -> 0 | J3: =C3-F3 -> 0
A4: 11Y5DH1JB07W6JPZBL | B4: 31 | C4: =_xlfn.XLOOKUP(Recon!A4,[1]Backup!AJ:AJ,[1]Backup!L:L) -> 240.27 | D4: =_xlfn.XLOOKUP(Recon!A4,[1]Backup!AJ:AJ,[1]Backup!K:K) -> 8.16918 | E4: =SUMIF('[1]PO Report'!A:A,Recon!A4,'[1]PO Report'!P:P) -> 31 | F4: =VLOOKUP(A4,'[1]PO Report'!$A:$Z,15,0) -> 240.27 | H4: =B4-E4 -> 0 | J4: =C4-F4 -> 0
A5: 13O47WAGB076CNH34R | B5: 4 | C5: =_xlfn.XLOOKUP(Recon!A5,[1]Backup!AJ:AJ,[1]Backup!L:L) -> 121.25 | D5: =_xlfn.XLOOKUP(Recon!A5,[1]Backup!AJ:AJ,[1]Backup!K:K) -> 4.1225 | E5: =SUMIF('[1]PO Report'!A:A,Recon!A5,'[1]PO Report'!P:P) -> 4 | F5: =VLOOKUP(A5,'[1]PO Report'!$A:$Z,15,0) -> 121.25 | H5: =B5-E5 -> 0 | J5: =C5-F5 -> 0
A6: 16QFG5EWB07W6JB7N7 | B6: 6 | C6: =_xlfn.XLOOKUP(Recon!A6,[1]Backup!AJ:AJ,[1]Backup!L:L) -> 210.52 | D6: =_xlfn.XLOOKUP(Recon!A6,[1]Backup!AJ:AJ,[1]Backup!K:K) -> 7.15768 | E6: =SUMIF('[1]PO Report'!A:A,Recon!A6,'[1]PO Report'!P:P) -> 6 | F6: =VLOOKUP(A6,'[1]PO Report'!$A:$Z,15,0) -> 210.52 | H6: =B6-E6 -> 0 | J6: =C6-F6 -> 0
A7: 172UACJHB01MCXJWD1 | B7: 66 | C7: =_xlfn.XLOOKUP(Recon!A7,[1]Backup!AJ:AJ,[1]Backup!L:L) -> 89.17 | D7: =_xlfn.XLOOKUP(Recon!A7,[1]Backup!AJ:AJ,[1]Backup!K:K) -> 3.03178 | E7: =SUMIF('[1]PO Report'!A:A,Recon!A7,'[1]PO Report'!P:P) -> 66 | F7: =VLOOKUP(A7,'[1]PO Report'!$A:$Z,15,0) -> 89.17 | H7: =B7-E7 -> 0 | J7: =C7-F7 -> 0
A8: 17D6YHERB0074486GA | B8: 4 | C8: =_xlfn.XLOOKUP(Recon!A8,[1]Backup!AJ:AJ,[1]Backup!L:L) -> 23.42 | D8: =_xlfn.XLOOKUP(Recon!A8,[1]Backup!AJ:AJ,[1]Backup!K:K) -> 0.79628 | E8: =SUMIF('[1]PO Report'!A:A,Recon!A8,'[1]PO Report'!P:P) -> 4 | F8: =VLOOKUP(A8,'[1]PO Report'!$A:$Z,15,0) -> 23.42 | H8: =B8-E8 -> 0 | J8: =C8-F8 -> 0
A9: 17D6YHERB00S67M430 | B9: 4 | C9: =_xlfn.XLOOKUP(Recon!A9,[1]Backup!AJ:AJ,[1]Backup!L:L) -> 35.13 | D9: =_xlfn.XLOOKUP(Recon!A9,[1]Backup!AJ:AJ,[1]Backup!K:K) -> 1.19442 | E9: =SUMIF('[1]PO Report'!A:A,Recon!A9,'[1]PO Report'!P:P) -> 4 | F9: =VLOOKUP(A9,'[1]PO Report'!$A:$Z,15,0) -> 35.13 | H9: =B9-E9 -> 0 | J9: =C9-F9 -> 0
A10: 17D6YHERB011N78DMA | B10: 3 | C10: =_xlfn.XLOOKUP(Recon!A10,[1]Backup!AJ:AJ,[1]Backup!L:L) -> 221.07 | D10: =_xlfn.XLOOKUP(Recon!A10,[1]Backup!AJ:AJ,[1]Backup!K:K) -> 7.51638 | E10: =SUMIF('[1]PO Report'!A:A,Recon!A10,'[1]PO Report'!P:P) -> 3 | F10: =VLOOKUP(A10,'[1]PO Report'!$A:$Z,15,0) -> 221.07 | H10: =B10-E10 -> 0 | J10: =C10-F10 -> 0
A11: 17D6YHERB01C4HCSOC | B11: 16 | C11: =_xlfn.XLOOKUP(Recon!A11,[1]Backup!AJ:AJ,[1]Backup!L:L) -> 23.42 | D11: =_xlfn.XLOOKUP(Recon!A11,[1]Backup!AJ:AJ,[1]Backup!K:K) -> 0.79628 | E11: =SUMIF('[1]PO Report'!A:A,Recon!A11,'[1]PO Report'!P:P) -> 16 | F11: =VLOOKUP(A11,'[1]PO Report'!$A:$Z,15,0) -> 23.42 | H11: =B11-E11 -> 0 | J11: =C11-F11 -> 0
A12: 17D6YHERB01MT5WL4M | B12: 24 | C12: =_xlfn.XLOOKUP(Recon!A12,[1]Backup!AJ:AJ,[1]Backup!L:L) -> 75.41 | D12: =_xlfn.XLOOKUP(Recon!A12,[1]Backup!AJ:AJ,[1]Backup!K:K) -> 2.56394 | E12: =SUMIF('[1]PO Report'!A:A,Recon!A12,'[1]PO Report'!P:P) -> 24 | F12: =VLOOKUP(A12,'[1]PO Report'!$A:$Z,15,0) -> 75.41 | H12: =B12-E12 -> 0 | J12: =C12-F12 -> 0
A13: 17D6YHERB01MT5WLHY | B13: 8 | C13: =_xlfn.XLOOKUP(Recon!A13,[1]Backup!AJ:AJ,[1]Backup!L:L) -> 75.41 | D13: =_xlfn.XLOOKUP(Recon!A13,[1]Backup!AJ:AJ,[1]Backup!K:K) -> 2.56394 | E13: =SUMIF('[1]PO Report'!A:A,Recon!A13,'[1]PO Report'!P:P) -> 8 | F13: =VLOOKUP(A13,'[1]PO Report'!$A:$Z,15,0) -> 75.41 | H13: =B13-E13 -> 0 | J13: =C13-F13 -> 0
A14: 17D6YHERB01MT5WMMG | B14: 24 | C14: =_xlfn.XLOOKUP(Recon!A14,[1]Backup!AJ:AJ,[1]Backup!L:L) -> 75.41 | D14: =_xlfn.XLOOKUP(Recon!A14,[1]Backup!AJ:AJ,[1]Backup!K:K) -> 2.56394 | E14: =SUMIF('[1]PO Report'!A:A,Recon!A14,'[1]PO Report'!P:P) -> 24 | F14: =VLOOKUP(A14,'[1]PO Report'!$A:$Z,15,0) -> 75.41 | H14: =B14-E14 -> 0 | J14: =C14-F14 -> 0
... A17: 17D6YHERB0797FYB3K | B17: 28 | C17: =_xlfn.XLOOKUP(Recon!A17,[1]Backup!AJ:AJ,[1]Backup!L:L) -> 43.92 | D17: =_xlfn.XLOOKUP(Recon!A17,[1]Backup!AJ:AJ,[1]Backup!K:K) -> 1.49328 | E17: =SUMIF('[1]PO Report'!A:A,Recon!A17,'[1]PO Report'!P:P) -> 28 | F17: =VLOOKUP(A17,'[1]PO Report'!$A:$Z,15,0) -> 43.92 | H17: =B17-E17 -> 0 | J17: =C17-F17 -> 0
A18: 17D6YHERB0797JRLQC | B18: 36 | C18: =_xlfn.XLOOKUP(Recon!A18,[1]Backup!AJ:AJ,[1]Backup!L:L) -> 43.92 | D18: =_xlfn.XLOOKUP(Recon!A18,[1]Backup!AJ:AJ,[1]Backup!K:K) -> 1.49328 | E18: =SUMIF('[1]PO Report'!A:A,Recon!A18,'[1]PO Report'!P:P) -> 32 | F18: =VLOOKUP(A18,'[1]PO Report'!$A:$Z,15,0) -> 43.92 | H18: =B18-E18 -> 4 | I18: =H18*D18 -> 5.97312 | J18: =C18-F18 -> 0
A19: 17D6YHERB0797LMGXH | B19: 4 | C19: =_xlfn.XLOOKUP(Recon!A19,[1]Backup!AJ:AJ,[1]Backup!L:L) -> 43.92 | D19: =_xlfn.XLOOKUP(Recon!A19,[1]Backup!AJ:AJ,[1]Backup!K:K) -> 1.49328 | E19: =SUMIF('[1]PO Report'!A:A,Recon!A19,'[1]PO Report'!P:P) -> 4 | F19: =VLOOKUP(A19,'[1]PO Report'!$A:$Z,15,0) -> 43.92 | H19: =B19-E19 -> 0 | J19: =C19-F19 -> 0
A20: 17D6YHERB079VVQS1R | B20: 2 | C20: =_xlfn.XLOOKUP(Recon!A20,[1]Backup!AJ:AJ,[1]Backup!L:L) -> 131.38 | D20: =_xlfn.XLOOKUP(Recon!A20,[1]Backup!AJ:AJ,[1]Backup!K:K) -> 4.46692 | E20: =SUMIF('[1]PO Report'!A:A,Recon!A20,'[1]PO Report'!P:P) -> 2 | F20: =VLOOKUP(A20,'[1]PO Report'!$A:$Z,15,0) -> 131.38 | H20: =B20-E20 -> 0 | J20: =C20-F20 -> 0
A21: 17D6YHERB07HZQT8JG | B21: 8 | C21: =_xlfn.XLOOKUP(Recon!A21,[1]Backup!AJ:AJ,[1]Backup!L:L) -> 73.34 | D21: =_xlfn.XLOOKUP(Recon!A21,[1]Backup!AJ:AJ,[1]Backup!K:K) -> 2.49356 | E21: =SUMIF('[1]PO Report'!A:A,Recon!A21,'[1]PO Report'!P:P) -> 8 | F21: =VLOOKUP(A21,'[1]PO Report'!$A:$Z,15,0) -> 73.34 | H21: =B21-E21 -> 0 | J21: =C21-F21 -> 0
A22: 17D6YHERB07W4DHXFT | B22: 56 | C22: =_xlfn.XLOOKUP(Recon!A22,[1]Backup!AJ:AJ,[1]Backup!L:L) -> 32.21 | D22: =_xlfn.XLOOKUP(Recon!A22,[1]Backup!AJ:AJ,[1]Backup!K:K) -> 1.09514 | E22: =SUMIF('[1]PO Report'!A:A,Recon!A22,'[1]PO Report'!P:P) -> 56 | F22: =VLOOKUP(A22,'[1]PO Report'!$A:$Z,15,0) -> 32.21 | H22: =B22-E22 -> 0 | J22: =C22-F22 -> 0
A23: 17D6YHERB07W6GVS5C | B23: 40 | C23: =_xlfn.XLOOKUP(Recon!A23,[1]Backup!AJ:AJ,[1]Backup!L:L) -> 44.84 | D23: =_xlfn.XLOOKUP(Recon!A23,[1]Backup!AJ:AJ,[1]Backup!K:K) -> 1.52456 | E23: =SUMIF('[1]PO Report'!A:A,Recon!A23,'[1]PO Report'!P:P) -> 40 | F23: =VLOOKUP(A23,'[1]PO Report'!$A:$Z,15,0) -> 44.84 | H23: =B23-E23 -> 0 | J23: =C23-F23 -> 0
A24: 17D6YHERB07W6JB7N7 | B24: 1 | C24: =_xlfn.XLOOKUP(Recon!A24,[1]Backup!AJ:AJ,[1]Backup!L:L) -> 210.52 | D24: =_xlfn.XLOOKUP(Recon!A24,[1]Backup!AJ:AJ,[1]Backup!K:K) -> 7.15768 | E24: =SUMIF('[1]PO Report'!A:A,Recon!A24,'[1]PO Report'!P:P) -> 1 | F24: =VLOOKUP(A24,'[1]PO Report'!$A:$Z,15,0) -> 210.52 | H24: =B24-E24 -> 0 | J24: =C24-F24 -> 0
A25: 17D6YHERB07W6JPVP3 | B25: 4 | C25: =_xlfn.XLOOKUP(Recon!A25,[1]Backup!AJ:AJ,[1]Backup!L:L) -> 74.84 | D25: =_xlfn.XLOOKUP(Recon!A25,[1]Backup!AJ:AJ,[1]Backup!K:K) -> 2.54456 | E25: =SUMIF('[1]PO Report'!A:A,Recon!A25,'[1]PO Report'!P:P) -> 4 | F25: =VLOOKUP(A25,'[1]PO Report'!$A:$Z,15,0) -> 74.84 | H25: =B25-E25 -> 0 | J25: =C25-F25 -> 0
A26: 17D6YHERB07W7K29YM | B26: 6 | C26: =_xlfn.XLOOKUP(Recon!A26,[1]Backup!AJ:AJ,[1]Backup!L:L) -> 29 | D26: =_xlfn.XLOOKUP(Recon!A26,[1]Backup!AJ:AJ,[1]Backup!K:K) -> 0.986 | E26: =SUMIF('[1]PO Report'!A:A,Recon!A26,'[1]PO Report'!P:P) -> 6 | F26: =VLOOKUP(A26,'[1]PO Report'!$A:$Z,15,0) -> 29 | H26: =B26-E26 -> 0 | J26: =C26-F26 -> 0
A27: 17D6YHERB07W7KFLBN | B27: 6 | C27: =_xlfn.XLOOKUP(Recon!A27,[1]Backup!AJ:AJ,[1]Backup!L:L) -> 29 | D27: =_xlfn.XLOOKUP(Recon!A27,[1]Backup!AJ:AJ,[1]Backup!K:K) -> 0.986 | E27: =SUMIF('[1]PO Report'!A:A,Recon!A27,'[1]PO Report'!P:P) -> 6 | F27: =VLOOKUP(A27,'[1]PO Report'!$A:$Z,15,0) -> 29 | H27: =B27-E27 -> 0 | J27: =C27-F27 -> 0
A28: 17D6YHERB07W7KNWK5 | B28: 8 | C28: =_xlfn.XLOOKUP(Recon!A28,[1]Backup!AJ:AJ,[1]Backup!L:L) -> 94.44 | D28: =_xlfn.XLOOKUP(Recon!A28,[1]Backup!AJ:AJ,[1]Backup!K:K) -> 3.21096 | E28: =SUMIF('[1]PO Report'!A:A,Recon!A28,'[1]PO Report'!P:P) -> 8 | F28: =VLOOKUP(A28,'[1]PO Report'!$A:$Z,15,0) -> 94.44 | H28: =B28-E28 -> 0 | J28: =C28-F28 -> 0
A29: 17D6YHERB07W7LF6F1 | B29: 480 | C29: =_xlfn.XLOOKUP(Recon!A29,[1]Backup!AJ:AJ,[1]Backup!L:L) -> 29 | D29: =_xlfn.XLOOKUP(Recon!A29,[1]Backup!AJ:AJ,[1]Backup!K:K) -> 0.986 | E29: =SUMIF('[1]PO Report'!A:A,Recon!A29,'[1]PO Report'!P:P) -> 480 | F29: =VLOOKUP(A29,'[1]PO Report'!$A:$Z,15,0) -> 29 | H29: =B29-E29 -> 0 | J29: =C29-F29 -> 0
A30: 17ETH86SB07W4DH5GL | B30: 4 | C30: =_xlfn.XLOOKUP(Recon!A30,[1]Backup!AJ:AJ,[1]Backup!L:L) -> 42.2 | D30: =_xlfn.XLOOKUP(Recon!A30,[1]Backup!AJ:AJ,[1]Backup!K:K) -> 1.4348 | E30: =SUMIF('[1]PO Report'!A:A,Recon!A30,'[1]PO Report'!P:P) -> 4 | F30: =VLOOKUP(A30,'[1]PO Report'!$A:$Z,15,0) -> 42.2 | H30: =B30-E30 -> 0 | J30: =C30-F30 -> 0
... A43: 1KW92RHQB078MHS3SC | B43: 16 | C43: =_xlfn.XLOOKUP(Recon!A43,[1]Backup!AJ:AJ,[1]Backup!L:L) -> 159.09 | D43: =_xlfn.XLOOKUP(Recon!A43,[1]Backup!AJ:AJ,[1]Backup!K:K) -> 5.40906 | E43: =SUMIF('[1]PO Report'!A:A,Recon!A43,'[1]PO Report'!P:P) -> 16 | F43: =VLOOKUP(A43,'[1]PO Report'!$A:$Z,15,0) -> 159.09 | H43: =B43-E43 -> 0 | J43: =C43-F43 -> 0
A44: 1KW92RHQB07VCS1895 | B44: 136 | C44: =_xlfn.XLOOKUP(Recon!A44,[1]Backup!AJ:AJ,[1]Backup!L:L) -> 35.13 | D44: =_xlfn.XLOOKUP(Recon!A44,[1]Backup!AJ:AJ,[1]Backup!K:K) -> 1.19442 | E44: =SUMIF('[1]PO Report'!A:A,Recon!A44,'[1]PO Report'!P:P) -> 132 | F44: =VLOOKUP(A44,'[1]PO Report'!$A:$Z,15,0) -> 35.13 | H44: =B44-E44 -> 4 | I44: =H44*D44 -> 4.77768 | J44: =C44-F44 -> 0
A45: 1KW92RHQB07W4DGQSX | B45: 32 | C45: =_xlfn.XLOOKUP(Recon!A45,[1]Backup!AJ:AJ,[1]Backup!L:L) -> 32.21 | D45: =_xlfn.XLOOKUP(Recon!A45,[1]Backup!AJ:AJ,[1]Backup!K:K) -> 1.09514 | E45: =SUMIF('[1]PO Report'!A:A,Recon!A45,'[1]PO Report'!P:P) -> 32 | F45: =VLOOKUP(A45,'[1]PO Report'!$A:$Z,15,0) -> 32.21 | H45: =B45-E45 -> 0 | J45: =C45-F45 -> 0
A46: 1KW92RHQB07W6JPZBL | B46: 90 | C46: =_xlfn.XLOOKUP(Recon!A46,[1]Backup!AJ:AJ,[1]Backup!L:L) -> 240.27 | D46: =_xlfn.XLOOKUP(Recon!A46,[1]Backup!AJ:AJ,[1]Backup!K:K) -> 8.16918 | E46: =SUMIF('[1]PO Report'!A:A,Recon!A46,'[1]PO Report'!P:P) -> 90 | F46: =VLOOKUP(A46,'[1]PO Report'!$A:$Z,15,0) -> 240.27 | H46: =B46-E46 -> 0 | J46: =C46-F46 -> 0
A47: 1KW92RHQB07W7LF6F1 | B47: 24 | C47: =_xlfn.XLOOKUP(Recon!A47,[1]Backup!AJ:AJ,[1]Backup!L:L) -> 29 | D47: =_xlfn.XLOOKUP(Recon!A47,[1]Backup!AJ:AJ,[1]Backup!K:K) -> 0.986 | E47: =SUMIF('[1]PO Report'!A:A,Recon!A47,'[1]PO Report'!P:P) -> 24 | F47: =VLOOKUP(A47,'[1]PO Report'!$A:$Z,15,0) -> 29 | H47: =B47-E47 -> 0 | J47: =C47-F47 -> 0
A48: 1KYIVKWCB004CM47VU | B48: 370 | C48: =_xlfn.XLOOKUP(Recon!A48,[1]Backup!AJ:AJ,[1]Backup!L:L) -> 17.56 | D48: =_xlfn.XLOOKUP(Recon!A48,[1]Backup!AJ:AJ,[1]Backup!K:K) -> 0.59704 | E48: =SUMIF('[1]PO Report'!A:A,Recon!A48,'[1]PO Report'!P:P) -> 370 | F48: =VLOOKUP(A48,'[1]PO Report'!$A:$Z,15,0) -> 17.56 | H48: =B48-E48 -> 0 | J48: =C48-F48 -> 0
A49: 1KYIVKWCB004PGM9KY | B49: 277 | C49: =_xlfn.XLOOKUP(Recon!A49,[1]Backup!AJ:AJ,[1]Backup!L:L) -> 248.87 | D49: =_xlfn.XLOOKUP(Recon!A49,[1]Backup!AJ:AJ,[1]Backup!K:K) -> 8.46158 | E49: =SUMIF('[1]PO Report'!A:A,Recon!A49,'[1]PO Report'!P:P) -> 277 | F49: =VLOOKUP(A49,'[1]PO Report'!$A:$Z,15,0) -> 248.87 | H49: =B49-E49 -> 0 | J49: =C49-F49 -> 0
A50: 1KYIVKWCB01DKGAQNG | B50: 8 | C50: =_xlfn.XLOOKUP(Recon!A50,[1]Backup!AJ:AJ,[1]Backup!L:L) -> 23.42 | D50: =_xlfn.XLOOKUP(Recon!A50,[1]Backup!AJ:AJ,[1]Backup!K:K) -> 0.79628 | E50: =SUMIF('[1]PO Report'!A:A,Recon!A50,'[1]PO Report'!P:P) -> 8 | F50: =VLOOKUP(A50,'[1]PO Report'!$A:$Z,15,0) -> 23.42 | H50: =B50-E50 -> 0 | J50: =C50-F50 -> 0
A51: 1KYIVKWCB01I252A34 | B51: 130 | C51: =_xlfn.XLOOKUP(Recon!A51,[1]Backup!AJ:AJ,[1]Backup!L:L) -> 16.39 | D51: =_xlfn.XLOOKUP(Recon!A51,[1]Backup!AJ:AJ,[1]Backup!K:K) -> 0.55726 | E51: =SUMIF('[1]PO Report'!A:A,Recon!A51,'[1]PO Report'!P:P) -> 130 | F51: =VLOOKUP(A51,'[1]PO Report'!$A:$Z,15,0) -> 16.39 | H51: =B51-E51 -> 0 | J51: =C51-F51 -> 0
A52: 1KYIVKWCB07W7KMK4Y | B52: 144 | C52: =_xlfn.XLOOKUP(Recon!A52,[1]Backup!AJ:AJ,[1]Backup!L:L) -> 69.03 | D52: =_xlfn.XLOOKUP(Recon!A52,[1]Backup!AJ:AJ,[1]Backup!K:K) -> 2.34702 | E52: =SUMIF('[1]PO Report'!A:A,Recon!A52,'[1]PO Report'!P:P) -> 144 | F52: =VLOOKUP(A52,'[1]PO Report'!$A:$Z,15,0) -> 69.03 | H52: =B52-E52 -> 0 | J52: =C52-F52 -> 0
A53: 1LQM129ZB00CJ5FP04 | B53: 8 | C53: =_xlfn.XLOOKUP(Recon!A53,[1]Backup!AJ:AJ,[1]Backup!L:L) -> 21.1 | D53: =_xlfn.XLOOKUP(Recon!A53,[1]Backup!AJ:AJ,[1]Backup!K:K) -> 0.7174 | E53: =SUMIF('[1]PO Report'!A:A,Recon!A53,'[1]PO Report'!P:P) -> 8 | F53: =VLOOKUP(A53,'[1]PO Report'!$A:$Z,15,0) -> 21.1 | H53: =B53-E53 -> 0 | J53: =C53-F53 -> 0
A54: 1LQM129ZB00ZOOKDU4 | B54: 44 | C54: =_xlfn.XLOOKUP(Recon!A54,[1]Backup!AJ:AJ,[1]Backup!L:L) -> 16.39 | D54: =_xlfn.XLOOKUP(Recon!A54,[1]Backup!AJ:AJ,[1]Backup!K:K) -> 0.55726 | E54: =SUMIF('[1]PO Report'!A:A,Recon!A54,'[1]PO Report'!P:P) -> 44 | F54: =VLOOKUP(A54,'[1]PO Report'!$A:$Z,15,0) -> 16.39 | H54: =B54-E54 -> 0 | J54: =C54-F54 -> 0
...

Sheet Dispute Summary
A2: Dispute Summary
A3: ASIN/PO combo Invalid | B3: #REF!
A4: Claim Qty > PO Qty | B4: 527.79764
B5: #REF!
A9: ASIN/PO combo Invalid
A10: PO | B10: ASIN | C10: QTY | D10: Rebate | E10: Total
A11: 7RAC5F9E | B11: B07TLX61W7 | C11: 4 | D11: 0.79628 | E11: #REF!
E12: #REF!
A14: Claim Qty > PO Qty
A15: PO | B15: ASIN | C15: PO Qty | D15: Claim QTY | E15: Over Claimed Qty | F15: Rebate Amt | G15: Total Over claim
A16: 17D6YHER | B16: B0797JRLQC | C16: 32 | D16: 36 | E16: 4 | F16: 1.49328 | G16: 5.97312
A17: 1KW92RHQ | B17: B07VCS1895 | C17: 132 | D17: 136 | E17: 4 | F17: 1.19442 | G17: 4.77768
A18: 1VBBCE3C | B18: B07W6HDNPG | C18: 8 | D18: 12 | E18: 4 | F18: 1.5283 | G18: 6.1132
A19: 1X4DXX4T | B19: B006ZLK9SQ | C19: 152 | D19: 315 | E19: 163 | F19: 0.697 | G19: 113.611
A20: 1X4DXX4T | B20: B07W5JKNB9 | C20: 28 | D20: 32 | E20: 4 | F20: 2.34702 | G20: 9.38808
A21: 2CLMXQWQ | B21: B01BGBJ8Y0 | C21: 144 | D21: 160 | E21: 16 | F21: 0.79628 | G21: 12.74048
A22: 2CLMXQWQ | B22: B07CGPZ3ZQ | C22: 268 | D22: 272 | E22: 4 | F22: 1.25562 | G22: 5.02248
A23: 2F7Y5WIX | B23: B07W4DHKTD | C23: 36 | D23: 40 | E23: 4 | F23: 2.85226 | G23: 11.40904
A24: 2LZI7R4T | B24: B077BT728N | C24: 2820 | D24: 2870 | E24: 50 | F24: 0.55726 | G24: 27.863
A25: 2M7QFTCO | B25: B07W6JKH1B | C25: 8 | D25: 16 | E25: 8 | F25: 1.09514 | G25: 8.76112
A26: 2R6FMUZD | B26: B006A2Q81M | C26: 8 | D26: 12 | E26: 4 | F26: 2.14982 | G26: 8.59928
A27: 2R6FMUZD | B27: B07W5JKFQC | C27: 80 | D27: 84 | E27: 4 | F27: 0.80716 | G27: 3.22864
... A55: 8SGS6BFX | B55: B00IRCDT7Y | C55: 844 | D55: 852 | E55: 8 | F55: 0.99552 | G55: 7.96416
G56: 527.79764
